Workbook
Name Checking: #REF!
Name Densities: INPUT_DATA!$H$4:$H$195
Name ENDCONNECTION: #REF!
Name Enthalpies: INPUT_DATA!$J$4:$J$195
Name EquipmentTags: LIST_OF_EQUIPMENT!$B$3:$B$31
Name FlowRates_kghr: INPUT_DATA!$D$4:$D$195
Name FlowRates_kgs: INPUT_DATA!$C$4:$C$195
Name FluidCategories: FluidList!$A$1:$A$6
Name LineNumbers: 'LIST OF LINES'!$B$4:$B$214
Name LineTags: INPUT_DATA!$A$4:$A$195
Name LOE_EquipNames: LIST_OF_EQUIPMENT!$A$3:$A$31
Name LOE_EquipTags: LIST_OF_EQUIPMENT!$B$3:$B$31
Name LOE_Pressures: LIST_OF_EQUIPMENT!$C$3:$C$31
Name LOE_Temperatures: LIST_OF_EQUIPMENT!$D$3:$D$31
Name LOL_LineNumbers: 'LIST OF LINES'!$B$4:$B$214
Name LOL_LineTags: 'LIST OF LINES'!$D$4:$D$214
Name MATERIALFORM: #REF!
Name NB: #REF!
Name PipeIDs: 'Pipe Table'!$A$2:$B$19
Name PipeReference: 'Pipe Table'!$A$2:$E$19
Name Pressures_bar: INPUT_DATA!$F$4:$F$195
Name Pressures_mbar: INPUT_DATA!$E$4:$E$195
Name SCHEDULE: #REF!
Name SHAPES: #REF!
Name StreamData: INPUT_DATA!$A$4:$J$195
Name TDS_Values: INPUT_DATA!$I$4:$I$195
Name Temperatures: INPUT_DATA!$G$4:$G$195
Name VALVELIST: #REF!
Name VALVEPURPOSE: #REF!

Sheet DATA_DICTIONARY
A1: DATA DICTIONARY - PROCESS MASTER DATA
A3: 1. SHEET RELATIONSHIPS
A4: Sheet Name | B4: Type | C4: Description
A5: INPUT_DATA | B5: Master sheet | C5: Contains all stream process data (flow, pressure, temp, etc.)
A6: LIST_OF_EQUIPMENT | B6: Dependent | C6: References INPUT_DATA for operating conditions and fluid connections
A7: LIST OF LINES | B7: Dependent | C7: References INPUT_DATA for sizing; Uses Pipe Table for selection
A8: LIST OF INSTRUMENTS | B8: Dependent | C8: References LIST OF LINES and INPUT_DATA for process conditions
A9: LIST OF VALVES | B9: Dependent | C9: References LIST OF LINES and INPUT_DATA for process conditions
A10: Pipe Table | B10: Reference | C10: Static lookup table for Schedule 40 pipe dimensions
A12: 2. NAMED RANGES
A13: Named Range | B13: Sheet | C13: Range | D13: Description
A14: StreamData | B14: INPUT_DATA | C14: $A$4:$J$195 | D14: All stream process data
A15: LineTags | B15: INPUT_DATA | C15: $A$4:$A$195 | D15: Line tag identifiers (primary key)
A16: FlowRates_kgs | B16: INPUT_DATA | C16: $C$4:$C$195 | D16: Flow rates in kg/s
A17: FlowRates_kghr | B17: INPUT_DATA | C17: $D$4:$D$195 | D17: Flow rates in kg/hr
A18: Pressures_mbar | B18: INPUT_DATA | C18: $E$4:$E$195 | D18: Pressures in mbar (absolute)
A19: Pressures_bar | B19: INPUT_DATA | C19: $F$4:$F$195 | D19: Pressures in bar (absolute)
A20: Temperatures | B20: INPUT_DATA | C20: $G$4:$G$195 | D20: Temperatures in °C
A21: Densities | B21: INPUT_DATA | C21: $H$4:$H$195 | D21: Densities in kg/m³
A22: TDS_Values | B22: INPUT_DATA | C22: $I$4:$I$195 | D22: Total Dissolved Solids in ppm
A23: Enthalpies | B23: INPUT_DATA | C23: $J$4:$J$195 | D23: Enthalpy in kJ/kg
A24: PipeReference | B24: Pipe Table | C24: $A$2:$E$19 | D24: Pipe sizing lookup table
... A27: LineNumbers | B27: LIST OF LINES | C27: $B$4:$B$214 | D27: Line numbers for validation
A29: 3. FLUID CATEGORIES
A30: Category | B30: Tag Range | C30: Description
A31: SEA WATER | B31: SW1 - SW17 | C31: Incoming seawater streams
A32: BRINE WATER | B32: B1 - B23 | C32: Concentrated brine streams
A33: DISTILLATE WATER | B33: D1 - D25 | C33: Product distillate streams
A34: STEAM | B34: ST1 - ST16 | C34: Steam and vapor streams
A35: NCG | B35: NCG1 - NCG12 | C35: Non-condensable gas streams
A36: FEED WATER | B36: FW1 - FW95 | C36: Feed water streams to effects
A38: 4. FORMULA PATTERNS (for reference)
A39: Purpose | B39: Formula Pattern | C39: Notes
A40: Lookup Pressure | B40: =IFERROR(INDEX(Pressures_bar,MATCH(LineTag,LineTags,0)),"") | C40: Get pressure by line tag
A41: Lookup Flow | B41: =IFERROR(INDEX(FlowRates_kgs,MATCH(LineTag,LineTags,0)),"") | C41: Get flow rate by line tag
A42: Lookup Temperature | B42: =IFERROR(INDEX(Temperatures,MATCH(LineTag,LineTags,0)),"") | C42: Get temperature by line tag
A43: Lookup Density | B43: =IFERROR(INDEX(Densities,MATCH(LineTag,LineTags,0)),"") | C43: Get density by line tag
A44: Pipe Size Selection | B44: =IFERROR(VLOOKUP(ROUNDUP(CalcID,-1),PipeReference,2,FALSE),"Check") -> Check | C44: Select pipe from calculated ID
A46: 5. DATA VALIDATION RULES
A47: Sheet | B47: Field | C47: Validation Type
...

Sheet INPUT_DATA
A1: Line Tag | B1: Description | C1: Flow Rate | D1: Flow Rate | E1: Pressure | F1: Pressure | G1: Temperature | H1: Density | I1: TDS | J1: Enthalpy (Ref: Pure Water, 0 C, 1 atm) | L1: NOTE: This sheet is the Master Data source
A2: Unit | C2: kg/s | D2: kg/hr | E2: mbar (a) | F2: bar a | G2: °C | H2: kg/m³ | I2: ppm | J2: kJ/kg | L2: Named ranges defined: LineTags, FlowRates_kgs, Pressures_bar, etc.
A3: SEA WATER | L3: See DATA_DICTIONARY sheet for full documentation
A4: SW1 | C4: 32.089504 | D4: =C4*3600 -> 115522.21 | E4: =F4*1000 -> 1000 | F4: 1 | G4: 30 | H4: 1026.3219 | I4: 39504.432 | J4: 448.44018
A5: SW2 | C5: 32.089504 | D5: =C5*3600 -> 115522.21 | E5: =F5*1000 -> 3500 | F5: 3.5 | G5: 30.086198 | H5: 1026.408 | I5: 39504.432 | J5: 448.78213
A6: SW3 | C6: 11.19 | D6: =C6*3600 -> 40284 | E6: =F6*1000 -> 3500 | F6: 3.5 | G6: 30.086304 | H6: 1026.41 | I6: 39504.432 | J6: 448.78255
A7: SW4 | C7: 11.189504 | D7: =C7*3600 -> 40282.214 | E7: =F7*1000 -> 3500 | F7: 3.5 | G7: 36 | H7: 1024.39 | I7: 39504.432 | J7: 448.78255
A8: SW5 | C8: =$C$7/3 -> 3.7298347 | D8: =$D$7/3 -> 13427.405 | E8: =F8*1000 -> 3500 | F8: 3.5 | G8: 36 | H8: 1024.39 | I8: 39504.432 | J8: 448.78255
A9: SW6 | C9: =$C$7/3 -> 3.7298347 | D9: =$D$7/3 -> 13427.405 | E9: =F9*1000 -> 3500 | F9: 3.5 | G9: 36 | H9: 1024.39 | I9: 39504.432 | J9: 448.78255
A10: SW7 | C10: =$C$7/3 -> 3.7298347 | D10: =$D$7/3 -> 13427.405 | E10: =F10*1000 -> 3500 | F10: 3.5 | G10: 36 | H10: 1024.39 | I10: 39504.432 | J10: 448.78255
A11: SW8 | C11: 9.9 | D11: =C11*3600 -> 35640 | E11: =F11*1000 -> 3500 | F11: 3.5 | G11: 30.09 | H11: 1024.39 | I11: 39504.432 | J11: 474.0602
A12: SW9 | C12: 9.9 | D12: =C12*3600 -> 35640 | E12: =F12*1000 -> 3500 | F12: 3.5 | G12: 36.45 | H12: 1026.41 | I12: 39504.432 | J12: 474.0602
A13: SW10 | C13: =$C$12/3 -> 3.3 | D13: =$D$12/3 -> 11880 | E13: =F13*1000 -> 3500 | F13: 3.5 | G13: 36.45 | H13: 1026.41 | I13: 39504.432 | J13: 474.0602
A14: SW11 | C14: =$C$12/3 -> 3.3 | D14: =$D$12/3 -> 11880 | E14: =F14*1000 -> 3500 | F14: 3.5 | G14: 36.45 | H14: 1026.41 | I14: 39504.432 | J14: 474.0602
A15: SW12 | C15: =$C$12/3 -> 3.3 | D15: =$D$12/3 -> 11880 | E15: =F15*1000 -> 3500 | F15: 3.5 | G15: 36.45 | H15: 1026.41 | I15: 39504.432 | J15: 474.0602
A16: SW13 | C16: 11 | D16: =C16*3600 -> 39600 | E16: =F16*1000 -> 3500 | F16: 3.5 | G16: 30.086304 | H16: 1024.2273 | I16: 39504.432 | J16: 472.25189
A17: SW14 | C17: 11 | D17: =C17*3600 -> 39600 | E17: =F17*1000 -> 3500 | F17: 3.5 | G17: 33.90938 | H17: 1026.408 | I17: 39504.432 | J17: 463.96298
A18: SW15 | C18: =$C$17/3 -> 3.6666667 | D18: =$D$17/3 -> 13200 | E18: =F18*1000 -> 3500 | F18: 3.5 | G18: 33.90938 | H18: 1026.408 | I18: 39504.432 | J18: 463.96298
A19: SW16 | C19: =$C$17/3 -> 3.6666667 | D19: =$D$17/3 -> 13200 | E19: =F19*1000 -> 3500 | F19: 3.5 | G19: 33.90938 | H19: 1026.408 | I19: 39504.432 | J19: 463.96298
A20: SW17 | C20: =$C$17/3 -> 3.6666667 | D20: =$D$17/3 -> 13200 | E20: =F20*1000 -> 3500 | F20: 3.5 | G20: 33.90938 | H20: 1026.408 | I20: 39504.432 | J20: 463.96298
A21: BRINE WATER
A22: B1 | B22: Siphon 1 | C22: =D22/3600 -> 4.07 | D22: 14652 | E22: 259.4 | G22: 66.55 | H22: 1043.56 | I22: 63600 | J22: 785.32514
A23: B2 | B23: Siphon 2 | C23: =D23/3600 -> 8.33 | D23: 29988 | E23: 219.6 | G23: 62.81 | H23: 1042.53 | I23: 62100 | J23: 758.99352
A24: B3 | B24: Siphon 3 | C24: =D24/3600 -> 12.73 | D24: 45828 | E24: 188 | G24: 59.4 | H24: 1041.71 | I24: 60900 | J24: 736.64506
A25: B4 | B25: Siphon 4 | C25: =D25/3600 -> 17.26 | D25: 62136 | E25: 161.8 | G25: 56.2 | H25: 1041.51 | I25: 60600 | J25: 721.74694
A26: B5 | B26: Siphon 5 | C26: =D26/3600 -> 21.81 | D26: 78516 | E26: 139.5 | G26: 53.1 | H26: 1041.37 | I26: 60400 | J26: 707.63335
A27: B6 | B27: Siphon 6 | C27: =D27/3600 -> 26.34 | D27: 94824 | E27: 119.8 | G27: 50 | H27: 1041.3 | I27: 60300 | J27: 694.7095
A28: B7 | B28: Siphon 7 | C28: =D28/3600 -> 31.02 | D28: 111672 | E28: 101.7 | G28: 46.72 | H28: 1041.16 | I28: 60100 | J28: 680.44776
A29: B8 | B29: Siphon 8 | C29: =D29/3600 -> 35.55 | D29: 127980 | E29: 94.6 | G29: 43.14 | H29: 1041.23 | I29: 60200 | J29: 667.45544
A30: B9 | B30: To brine tank | C30: =D30/3600 -> 39.83 | D30: 143388 | E30: 68 | G30: 39 | H30: 1041.51 | I30: 60600 | J30: 655.18615
A31: B10 | B31: Brine tank to Brine pump skid | C31: 39.833514 | D31: =C31*3600 -> 143400.65 | E31: =F31*1000 -> 2500 | F31: 2.5 | G31: 39.070967 | H31: 1039.7242 | I31: =I30 -> 60600 | J31: 655.4602
A32: B11 | C32: HOLD | D32: =C32*3600 -> #VALUE! | E32: =F32*1000 -> 2500 | F32: 2.5 | G32: 37.44739 | H32: 1040.3579 | J32: 649.17815
A33: B12 | C33: HOLD | D33: =C33*3600 -> #VALUE! | E33: =F33*1000 -> 2500 | F33: 2.5 | G33: 37.44739 | H33: 1040.3579 | J33: 649.17815
A34: B13 | C34: 18.925 | D34: =C34*3600 -> 68130 | E34: =F34*1000 -> 2500 | F34: 2.5 | G34: 37.44739 | H34: 1040.3579 | I34: 60600 | J34: 649.17815
A35: B14 | C35: 18.925 | D35: =C35*3600 -> 68130 | E35: =F35*1000 -> 2500 | F35: 2.5 | G35: 37.44739 | H35: 1040.3579 | I35: 60600 | J35: 649.17815
A36: B15 | B36: EFF-1 | C36: 1.84 | D36: =C36*60*60 -> 6624 | E36: =F36*1000 -> 2500 | F36: 2.5 | G36: 37.44739 | H36: 1040.3579 | I36: 60600 | J36: 649.17815
A37: B16 | B37: EFF-2 | C37: 1.84 | D37: =C37*60*60 -> 6624 | E37: =F37*1000 -> 2500 | F37: 2.5 | G37: 37.44739 | H37: 1040.3579 | I37: 60600 | J37: 649.17815
A38: B17 | B38: EFF-3 | C38: 1.83 | D38: =C38*60*60 -> 6588 | E38: =F38*1000 -> 2500 | F38: 2.5 | G38: 37.44739 | H38: 1040.3579 | I38: 60600 | J38: 649.17815
A39: B18 | B39: EFF-4 | C39: 2.31 | D39: =C39*60*60 -> 8316 | E39: =F39*1000 -> 2500 | F39: 2.5 | G39: 37.44739 | H39: 1040.3579 | I39: 60600 | J39: 649.17815
A40: B19 | B40: EFF-5 | C40: 2.31 | D40: =C40*60*60 -> 8316 | E40: =F40*1000 -> 2500 | F40: 2.5 | G40: 37.44739 | H40: 1040.3579 | I40: 60600 | J40: 649.17815
...

Sheet LIST_OF_EQUIPMENT
A1: Equipment Name | B1: Equipment Tag No. | C1: Operating Pressure | D1: Operating Temperature | E1: Fluid_In_1 | F1: Fluid_In_2 | G1: Fluid_In_3 | H1: Fluid_In_4 | I1: Fluid_In_5 | J1: Fluid_Out_1 | K1: Fluid_Out_2 | L1: Fluid_Out_3 | M1: Fluid_Out_4
A2: Units | C2: mbar (a) | D2: °C
A3: Low Temperature Flash Vessel | B3: LTFV | C3: =INPUT_DATA!E84 -> 67.969461 | D3: =INPUT_DATA!G84 -> 38.388778 | E3: =INPUT_DATA!A64 -> D19 | J3: =INPUT_DATA!A65 -> D20 | K3: =INPUT_DATA!A84 -> S13
A4: High Temperature Flash Vessel | B4: HTFV | C4: =INPUT_DATA!E85 -> 320.45592 | D4: =INPUT_DATA!G85 -> 70.6 | E4: =INPUT_DATA!A67 -> D22 | J4: =INPUT_DATA!A68 -> D23 | K4: =INPUT_DATA!A85 -> S14
A5: MED Train - 1 | B5: MED - E1 | C5: =INPUT_DATA!E86 -> 320.46 | D5: =INPUT_DATA!G86 -> 70.6 | E5: =INPUT_DATA!A84 -> S13 | F5: =INPUT_DATA!A85 -> S14 | G5: =INPUT_DATA!A101 -> F1 | J5: =INPUT_DATA!A22 -> B1 | K5: =INPUT_DATA!A46 -> D1 | L5: =INPUT_DATA!A72 -> S1 | M5: =INPUT_DATA!A88 -> NCG1
A6: MED Train - 1 | B6: MED - E2 | C6: =INPUT_DATA!E72 -> 259.4 | D6: =INPUT_DATA!G72 -> 66.55 | E6: =INPUT_DATA!A72 -> S1 | F6: =INPUT_DATA!A88 -> NCG1 | G6: =INPUT_DATA!A112 -> F2 | H6: =INPUT_DATA!A22 -> B1 | I6: =INPUT_DATA!A46 -> D1 | J6: =INPUT_DATA!A23 -> B2 | K6: =INPUT_DATA!A47 -> D2 | L6: =INPUT_DATA!A73 -> S2 | M6: =INPUT_DATA!A89 -> NCG2
A7: MED Train - 1 | B7: MED - E3 | C7: =INPUT_DATA!E73 -> 219.6 | D7: =INPUT_DATA!G73 -> 62.81 | E7: =INPUT_DATA!A73 -> S2 | F7: =INPUT_DATA!A89 -> NCG2 | G7: =INPUT_DATA!A123 -> F3 | H7: =INPUT_DATA!A23 -> B2 | I7: =INPUT_DATA!A47 -> D2 | J7: =INPUT_DATA!A24 -> B3 | K7: =INPUT_DATA!A48 -> D3 | L7: =INPUT_DATA!A74 -> S3 | M7: =INPUT_DATA!A90 -> NCG3
A8: MED Train - 2 | B8: MED - E4 | C8: =INPUT_DATA!E74 -> 188 | D8: =INPUT_DATA!G74 -> 59.4 | E8: =INPUT_DATA!A74 -> S3 | F8: =INPUT_DATA!A90 -> NCG3 | G8: =INPUT_DATA!A134 -> F4 | H8: =INPUT_DATA!A24 -> B3 | I8: =INPUT_DATA!A48 -> D3 | J8: =INPUT_DATA!A25 -> B4 | K8: =INPUT_DATA!A49 -> D4 | L8: =INPUT_DATA!A75 -> S4 | M8: =INPUT_DATA!A91 -> NCG4
A9: MED Train - 2 | B9: MED - E5 | C9: =INPUT_DATA!E75 -> 161.8 | D9: =INPUT_DATA!G75 -> 56.2 | E9: =INPUT_DATA!A75 -> S4 | F9: =INPUT_DATA!A91 -> NCG4 | G9: =INPUT_DATA!A145 -> F5 | H9: =INPUT_DATA!A25 -> B4 | I9: =INPUT_DATA!A49 -> D4 | J9: =INPUT_DATA!A26 -> B5 | K9: =INPUT_DATA!A50 -> D5 | L9: =INPUT_DATA!A76 -> S5 | M9: =INPUT_DATA!A92 -> NCG5
A10: MED Train - 2 | B10: MED - E6 | C10: =INPUT_DATA!E76 -> 139.5 | D10: =INPUT_DATA!G76 -> 53.1 | E10: =INPUT_DATA!A76 -> S5 | F10: =INPUT_DATA!A92 -> NCG5 | G10: =INPUT_DATA!A156 -> F6 | H10: =INPUT_DATA!A26 -> B5 | I10: =INPUT_DATA!A50 -> D5 | J10: =INPUT_DATA!A27 -> B6 | K10: =INPUT_DATA!A51 -> D6 | L10: =INPUT_DATA!A77 -> S6 | M10: =INPUT_DATA!A93 -> NCG6
A11: MED Train - 3 | B11: MED - E7 | C11: =INPUT_DATA!E77 -> 119.8 | D11: =INPUT_DATA!G77 -> 50 | E11: =INPUT_DATA!A77 -> S6 | F11: =INPUT_DATA!A93 -> NCG6 | G11: =INPUT_DATA!A167 -> F7 | H11: =INPUT_DATA!A27 -> B6 | I11: =INPUT_DATA!A51 -> D6 | J11: =INPUT_DATA!A28 -> B7 | K11: =INPUT_DATA!A52 -> D7 | L11: =INPUT_DATA!A78 -> S7 | M11: =INPUT_DATA!A94 -> NCG7
A12: MED Train - 3 | B12: MED - E8 | C12: =INPUT_DATA!E78 -> 101.7 | D12: =INPUT_DATA!G78 -> 46.72 | E12: =INPUT_DATA!A78 -> S7 | F12: =INPUT_DATA!A94 -> NCG7 | G12: =INPUT_DATA!A178 -> F8 | H12: =INPUT_DATA!A28 -> B7 | I12: =INPUT_DATA!A52 -> D7 | J12: =INPUT_DATA!A29 -> B8 | K12: =INPUT_DATA!A53 -> D8 | L12: =INPUT_DATA!A79 -> S8 | M12: =INPUT_DATA!A95 -> NCG8
A13: MED Train - 3 | B13: MED - E9 | C13: =INPUT_DATA!E79 -> 84.6 | D13: =INPUT_DATA!G79 -> 43.14 | E13: =INPUT_DATA!A79 -> S8 | F13: =INPUT_DATA!A95 -> NCG8 | G13: =INPUT_DATA!A189 -> F9 | H13: =INPUT_DATA!A29 -> B8 | I13: =INPUT_DATA!A53 -> D8 | J13: =INPUT_DATA!A30 -> B9 | K13: =INPUT_DATA!A54 -> D9 | L13: =INPUT_DATA!A80 -> S9 | M13: =INPUT_DATA!A96 -> NCG9
A14: Final Condenser | B14: FC | C14: =INPUT_DATA!E96 -> 82 | D14: =INPUT_DATA!G96 -> 41.91 | E14: =INPUT_DATA!A16 -> SW13 | F14: =INPUT_DATA!A96 -> NCG9 | J14: =INPUT_DATA!A17 -> SW14 | K14: =INPUT_DATA!A97 -> NCG10
A15: Brine Plate Heat Exchanger | B15: BPHE | E15: =INPUT_DATA!A31 -> B10 | F15: =INPUT_DATA!A11 -> SW8 | J15: =INPUT_DATA!A32 -> B11 | K15: =INPUT_DATA!A12 -> SW9
A16: Distillate Plate Heat Exchanger | B16: DPHE | E16: =INPUT_DATA!A56 -> D11 | F16: =INPUT_DATA!A6 -> SW3 | J16: =INPUT_DATA!A33 -> B12 | K16: =INPUT_DATA!A7 -> SW4
A17: Brine Tank | B17: BT | C17: =INPUT_DATA!E30 -> 68 | D17: =INPUT_DATA!G30 -> 39 | E17: =INPUT_DATA!A30 -> B9 | J17: =INPUT_DATA!A31 -> B10
A18: Distillate Tank | B18: DT | C18: =INPUT_DATA!E54 -> 84.6 | D18: =INPUT_DATA!G54 -> 42.404474 | E18: =INPUT_DATA!A54 -> D9 | F18: =INPUT_DATA!A70 -> D25 | J18: =INPUT_DATA!A55 -> D10
A19: Sea Water Pump | B19: SWP | E19: =INPUT_DATA!A4 -> SW1 | J19: =INPUT_DATA!A5 -> SW2
A20: Brine Pump | B20: BP | E20: =INPUT_DATA!A30 -> B9 | J20: =INPUT_DATA!A31 -> B10
A21: Distillate Pump | B21: DP | E21: =INPUT_DATA!A55 -> D10 | J21: =INPUT_DATA!A56 -> D11
A22: Initial Fill Pump | B22: IFP | E22: =INPUT_DATA!A58 -> D13 | J22: =INPUT_DATA!A60 -> D15
A23: Make Up Pump | B23: MP | E23: =INPUT_DATA!A59 -> D14 | J23: =INPUT_DATA!A61 -> D16 | K23: =INPUT_DATA!A62 -> D17 | L23: =INPUT_DATA!A63 -> D18
A24: LTFV-Re Circulation Pump | B24: LTFV-RCP | J24: =INPUT_DATA!A64 -> D19
A25: HTFV-Re Circulation Pump | B25: HTFV-RCP | J25: =INPUT_DATA!A67 -> D22
A26: LTFV-Extraction Pump | B26: LTFV-EP | E26: =INPUT_DATA!A66 -> D21
A27: HTFV-Extraction Pump | B27: LTFV-EP | E27: =INPUT_DATA!A69 -> D24
A28: Distillate Storage Tank | B28: DST | C28: =INPUT_DATA!E57 -> 0 | D28: =INPUT_DATA!G57 -> 0 | E28: =INPUT_DATA!A57 -> D12 | J28: =INPUT_DATA!A58 -> D13 | K28: =INPUT_DATA!A59 -> D14
A29: Anti-Scalant Tank | B29: AST
A30: Anti-Foam Tank | B30: AFT
A31: Acid Cleaning Tank | B31: ACT

Sheet LIST OF LINES
A1: S.No | B1: Line No | C1: Fluid | D1: Input Data | E1: Flow Rate | F1: Density | G1: Calculated Velocity | H1: Calculated Inner diameter | I1: Selected Inner diameter | J1: Actual Velocity
D2: Tag No. | E2: kg/s | F2: kg/m3 | G2: m/s | H2: mm | I2: mm | J2: m/s
A3: SEA WATER LINE
A4: 1 | B4: 200-40-SS-SW-01 | C4: Sea water | D4: =INPUT_DATA!A4 -> SW1 | E4: =IFERROR(INDEX(FlowRates_kgs,MATCH(D4,LineTags,0)),"") -> 32.089504 | F4: =IFERROR(INDEX(Densities,MATCH(D4,LineTags,0)),"") -> 1026.3219 | G4: 1.6 | H4: =IFERROR(SQRT((4*E4)/(PI()*F4*G4))*1000,"") -> 157.73743 | I4: =IFERROR(VLOOKUP(ROUNDUP(H4,-1),PipeReference,2,TRUE),"Check Size") -> 202.74 | J4: =IFERROR((4*E4)/(PI()*F4*(I4/1000)^2),"") -> 0.96852457
A5: =A4+1 -> 2 | B5: 200-40-SS-SW-02 | C5: Sea water | D5: =INPUT_DATA!A5 -> SW2 | E5: =IFERROR(INDEX(FlowRates_kgs,MATCH(D5,LineTags,0)),"") -> 32.089504 | F5: =IFERROR(INDEX(Densities,MATCH(D5,LineTags,0)),"") -> 1026.408 | G5: 1.6 | H5: =IFERROR(SQRT((4*E5)/(PI()*F5*G5))*1000,"") -> 157.73082 | I5: =IFERROR(VLOOKUP(ROUNDUP(H5,-1),PipeReference,2,TRUE),"Check Size") -> 202.74 | J5: =IFERROR((4*E5)/(PI()*F5*(I5/1000)^2),"") -> 0.96844329
A6: =A5+1 -> 3 | B6: 100-40-SS-SW-03 | C6: Sea water | D6: =INPUT_DATA!A6 -> SW3 | E6: =IFERROR(INDEX(FlowRates_kgs,MATCH(D6,LineTags,0)),"") -> 11.19 | F6: =IFERROR(INDEX(Densities,MATCH(D6,LineTags,0)),"") -> 1026.41 | G6: 2 | H6: =IFERROR(SQRT((4*E6)/(PI()*F6*G6))*1000,"") -> 83.309527 | I6: =IFERROR(VLOOKUP(ROUNDUP(H6,-1),PipeReference,2,TRUE),"Check Size") -> 102.26 | J6: =IFERROR((4*E6)/(PI()*F6*(I6/1000)^2),"") -> 1.3274182
A7: =A6+1 -> 4 | B7: 100-40-SS-SW-04 | C7: Sea water | D7: =INPUT_DATA!A7 -> SW4 | E7: =IFERROR(INDEX(FlowRates_kgs,MATCH(D7,LineTags,0)),"") -> 11.189504 | F7: =IFERROR(INDEX(Densities,MATCH(D7,LineTags,0)),"") -> 1024.39 | G7: 2 | H7: =IFERROR(SQRT((4*E7)/(PI()*F7*G7))*1000,"") -> 83.389777 | I7: =IFERROR(VLOOKUP(ROUNDUP(H7,-1),PipeReference,2,TRUE),"Check Size") -> 102.26 | J7: =IFERROR((4*E7)/(PI()*F7*(I7/1000)^2),"") -> 1.3299767
A8: =A7+1 -> 5 | B8: 65-40-SS-SW-05 | C8: Sea water | D8: =INPUT_DATA!A8 -> SW5 | E8: =IFERROR(INDEX(FlowRates_kgs,MATCH(D8,LineTags,0)),"") -> 3.7298347 | F8: =IFERROR(INDEX(Densities,MATCH(D8,LineTags,0)),"") -> 1024.39 | G8: 2 | H8: =IFERROR(SQRT((4*E8)/(PI()*F8*G8))*1000,"") -> 48.14511 | I8: =IFERROR(VLOOKUP(ROUNDUP(H8,-1),PipeReference,2,TRUE),"Check Size") -> 52.48 | J8: =IFERROR((4*E8)/(PI()*F8*(I8/1000)^2),"") -> 1.6832426
A9: =A8+1 -> 6 | B9: 65-40-SS-SW-06 | C9: Sea water | D9: =INPUT_DATA!A9 -> SW6 | E9: =IFERROR(INDEX(FlowRates_kgs,MATCH(D9,LineTags,0)),"") -> 3.7298347 | F9: =IFERROR(INDEX(Densities,MATCH(D9,LineTags,0)),"") -> 1024.39 | G9: 2 | H9: =IFERROR(SQRT((4*E9)/(PI()*F9*G9))*1000,"") -> 48.14511 | I9: =IFERROR(VLOOKUP(ROUNDUP(H9,-1),PipeReference,2,TRUE),"Check Size") -> 52.48 | J9: =IFERROR((4*E9)/(PI()*F9*(I9/1000)^2),"") -> 1.6832426
A10: =A9+1 -> 7 | B10: 65-40-SS-SW-07 | C10: Sea water | D10: =INPUT_DATA!A10 -> SW7 | E10: =IFERROR(INDEX(FlowRates_kgs,MATCH(D10,LineTags,0)),"") -> 3.7298347 | F10: =IFERROR(INDEX(Densities,MATCH(D10,LineTags,0)),"") -> 1024.39 | G10: 2 | H10: =IFERROR(SQRT((4*E10)/(PI()*F10*G10))*1000,"") -> 48.14511 | I10: =IFERROR(VLOOKUP(ROUNDUP(H10,-1),PipeReference,2,TRUE),"Check Size") -> 52.48 | J10: =IFERROR((4*E10)/(PI()*F10*(I10/1000)^2),"") -> 1.6832426
A11: =A10+1 -> 8 | B11: 100-40-SS-SW-08 | C11: Sea water | D11: =INPUT_DATA!A11 -> SW8 | E11: =IFERROR(INDEX(FlowRates_kgs,MATCH(D11,LineTags,0)),"") -> 9.9 | F11: =IFERROR(INDEX(Densities,MATCH(D11,LineTags,0)),"") -> 1024.39 | G11: 2 | H11: =IFERROR(SQRT((4*E11)/(PI()*F11*G11))*1000,"") -> 78.437726 | I11: =IFERROR(VLOOKUP(ROUNDUP(H11,-1),PipeReference,2,TRUE),"Check Size") -> 102.26 | J11: =IFERROR((4*E11)/(PI()*F11*(I11/1000)^2),"") -> 1.1767072
A12: =A11+1 -> 9 | B12: 100-40-SS-SW-09 | C12: Sea water | D12: =INPUT_DATA!A12 -> SW9 | E12: =IFERROR(INDEX(FlowRates_kgs,MATCH(D12,LineTags,0)),"") -> 9.9 | F12: =IFERROR(INDEX(Densities,MATCH(D12,LineTags,0)),"") -> 1026.41 | G12: 2 | H12: =IFERROR(SQRT((4*E12)/(PI()*F12*G12))*1000,"") -> 78.360504 | I12: =IFERROR(VLOOKUP(ROUNDUP(H12,-1),PipeReference,2,TRUE),"Check Size") -> 102.26 | J12: =IFERROR((4*E12)/(PI()*F12*(I12/1000)^2),"") -> 1.1743914
A13: =A12+1 -> 10 | B13: 65-40-SS-SW-10 | C13: Sea water | D13: =INPUT_DATA!A13 -> SW10 | E13: =IFERROR(INDEX(FlowRates_kgs,MATCH(D13,LineTags,0)),"") -> 3.3 | F13: =IFERROR(INDEX(Densities,MATCH(D13,LineTags,0)),"") -> 1026.41 | G13: 2 | H13: =IFERROR(SQRT((4*E13)/(PI()*F13*G13))*1000,"") -> 45.241458 | I13: =IFERROR(VLOOKUP(ROUNDUP(H13,-1),PipeReference,2,TRUE),"Check Size") -> 52.48 | J13: =IFERROR((4*E13)/(PI()*F13*(I13/1000)^2),"") -> 1.486331
A14: =A13+1 -> 11 | B14: 65-40-SS-SW-11 | C14: Sea water | D14: =INPUT_DATA!A14 -> SW11 | E14: =IFERROR(INDEX(FlowRates_kgs,MATCH(D14,LineTags,0)),"") -> 3.3 | F14: =IFERROR(INDEX(Densities,MATCH(D14,LineTags,0)),"") -> 1026.41 | G14: 2 | H14: =IFERROR(SQRT((4*E14)/(PI()*F14*G14))*1000,"") -> 45.241458 | I14: =IFERROR(VLOOKUP(ROUNDUP(H14,-1),PipeReference,2,TRUE),"Check Size") -> 52.48 | J14: =IFERROR((4*E14)/(PI()*F14*(I14/1000)^2),"") -> 1.486331
A15: =A14+1 -> 12 | B15: 65-40-SS-SW-12 | C15: Sea water | D15: =INPUT_DATA!A15 -> SW12 | E15: =IFERROR(INDEX(FlowRates_kgs,MATCH(D15,LineTags,0)),"") -> 3.3 | F15: =IFERROR(INDEX(Densities,MATCH(D15,LineTags,0)),"") -> 1026.41 | G15: 2 | H15: =IFERROR(SQRT((4*E15)/(PI()*F15*G15))*1000,"") -> 45.241458 | I15: =IFERROR(VLOOKUP(ROUNDUP(H15,-1),PipeReference,2,TRUE),"Check Size") -> 52.48 | J15: =IFERROR((4*E15)/(PI()*F15*(I15/1000)^2),"") -> 1.486331
A16: =A15+1 -> 13 | B16: 100-40-SS-SW-13 | C16: Sea water | D16: =INPUT_DATA!A16 -> SW13 | E16: =IFERROR(INDEX(FlowRates_kgs,MATCH(D16,LineTags,0)),"") -> 11 | F16: =IFERROR(INDEX(Densities,MATCH(D16,LineTags,0)),"") -> 1024.2273 | G16: 2 | H16: =IFERROR(SQRT((4*E16)/(PI()*F16*G16))*1000,"") -> 82.687189 | I16: =IFERROR(VLOOKUP(ROUNDUP(H16,-1),PipeReference,2,TRUE),"Check Size") -> 102.26 | J16: =IFERROR((4*E16)/(PI()*F16*(I16/1000)^2),"") -> 1.3076601
... A20: =A19+1 -> 17 | B20: 65-40-SS-SW-17 | C20: Sea water | D20: =INPUT_DATA!A20 -> SW17 | E20: =IFERROR(INDEX(FlowRates_kgs,MATCH(D20,LineTags,0)),"") -> 3.6666667 | F20: =IFERROR(INDEX(Densities,MATCH(D20,LineTags,0)),"") -> 1026.408 | G20: 2 | H20: =IFERROR(SQRT((4*E20)/(PI()*F20*G20))*1000,"") -> 47.688731 | I20: =IFERROR(VLOOKUP(ROUNDUP(H20,-1),PipeReference,2,TRUE),"Check Size") -> 52.48 | J20: =IFERROR((4*E20)/(PI()*F20*(I20/1000)^2),"") -> 1.6514821
A21: BRINE WATER LINE
A22: =A20+1 -> 18 | B22: 150-40-SS-BW-01 | C22: Brine | D22: =INPUT_DATA!A22 -> B1 | E22: =IFERROR(INDEX(FlowRates_kgs,MATCH(D22,LineTags,0)),"") -> 4.07 | F22: =IFERROR(INDEX(Densities,MATCH(D22,LineTags,0)),"") -> 1043.56 | G22: 0.4 | H22: =IFERROR(SQRT((4*E22)/(PI()*F22*G22))*1000,"") -> 111.4201 | I22: =IFERROR(VLOOKUP(ROUNDUP(H22,-1),PipeReference,2,TRUE),"Check Size") -> 154.08 | J22: =IFERROR((4*E22)/(PI()*F22*(I22/1000)^2),"") -> 0.20916767
A23: =A22+1 -> 19 | B23: 200-40-SS-BW-02 | C23: Brine | D23: =INPUT_DATA!A23 -> B2 | E23: =IFERROR(INDEX(FlowRates_kgs,MATCH(D23,LineTags,0)),"") -> 8.33 | F23: =IFERROR(INDEX(Densities,MATCH(D23,LineTags,0)),"") -> 1042.53 | G23: 0.4 | H23: =IFERROR(SQRT((4*E23)/(PI()*F23*G23))*1000,"") -> 159.47892 | I23: =IFERROR(VLOOKUP(ROUNDUP(H23,-1),PipeReference,2,TRUE),"Check Size") -> 202.74 | J23: =IFERROR((4*E23)/(PI()*F23*(I23/1000)^2),"") -> 0.24750711
A24: =A23+1 -> 20 | B24: 250-40-SS-BW-03 | C24: Brine | D24: =INPUT_DATA!A24 -> B3 | E24: =IFERROR(INDEX(FlowRates_kgs,MATCH(D24,LineTags,0)),"") -> 12.73 | F24: =IFERROR(INDEX(Densities,MATCH(D24,LineTags,0)),"") -> 1041.71 | G24: 0.3 | H24: =IFERROR(SQRT((4*E24)/(PI()*F24*G24))*1000,"") -> 227.73785 | I24: =IFERROR(VLOOKUP(ROUNDUP(H24,-1),PipeReference,2,TRUE),"Check Size") -> 254.56 | J24: =IFERROR((4*E24)/(PI()*F24*(I24/1000)^2),"") -> 0.24011062
A25: =A24+1 -> 21 | B25: 300-40-SS-BW-04 | C25: Brine | D25: =INPUT_DATA!A25 -> B4 | E25: =IFERROR(INDEX(FlowRates_kgs,MATCH(D25,LineTags,0)),"") -> 17.26 | F25: =IFERROR(INDEX(Densities,MATCH(D25,LineTags,0)),"") -> 1041.51 | G25: 0.3 | H25: =IFERROR(SQRT((4*E25)/(PI()*F25*G25))*1000,"") -> 265.20585 | I25: =IFERROR(VLOOKUP(ROUNDUP(H25,-1),PipeReference,2,TRUE),"Check Size") -> 303.64 | J25: =IFERROR((4*E25)/(PI()*F25*(I25/1000)^2),"") -> 0.22885979
A26: =A25+1 -> 22 | B26: 350-40-SS-BW-05 | C26: Brine | D26: =INPUT_DATA!A26 -> B5 | E26: =IFERROR(INDEX(FlowRates_kgs,MATCH(D26,LineTags,0)),"") -> 21.81 | F26: =IFERROR(INDEX(Densities,MATCH(D26,LineTags,0)),"") -> 1041.37 | G26: 0.25 | H26: =IFERROR(SQRT((4*E26)/(PI()*F26*G26))*1000,"") -> 326.59562 | I26: =IFERROR(VLOOKUP(ROUNDUP(H26,-1),PipeReference,2,TRUE),"Check Size") -> 333.34 | J26: =IFERROR((4*E26)/(PI()*F26*(I26/1000)^2),"") -> 0.23998597
A27: =A26+1 -> 23 | B27: 400-40-SS-BW-06 | C27: Brine | D27: =INPUT_DATA!A27 -> B6 | E27: =IFERROR(INDEX(FlowRates_kgs,MATCH(D27,LineTags,0)),"") -> 26.34 | F27: =IFERROR(INDEX(Densities,MATCH(D27,LineTags,0)),"") -> 1041.3 | G27: 0.25 | H27: =IFERROR(SQRT((4*E27)/(PI()*F27*G27))*1000,"") -> 358.92607 | I27: =IFERROR(VLOOKUP(ROUNDUP(H27,-1),PipeReference,2,TRUE),"Check Size") -> 381 | J27: =IFERROR((4*E27)/(PI()*F27*(I27/1000)^2),"") -> 0.22187076
A28: =A27+1 -> 24 | B28: 400-40-SS-BW-07 | C28: Brine | D28: =INPUT_DATA!A28 -> B7 | E28: =IFERROR(INDEX(FlowRates_kgs,MATCH(D28,LineTags,0)),"") -> 31.02 | F28: =IFERROR(INDEX(Densities,MATCH(D28,LineTags,0)),"") -> 1041.16 | G28: 0.3 | H28: =IFERROR(SQRT((4*E28)/(PI()*F28*G28))*1000,"") -> 355.59577 | I28: =IFERROR(VLOOKUP(ROUNDUP(H28,-1),PipeReference,2,TRUE),"Check Size") -> 381 | J28: =IFERROR((4*E28)/(PI()*F28*(I28/1000)^2),"") -> 0.26132712
A29: =A28+1 -> 25 | B29: 450-40-SS-BW-08 | C29: Brine | D29: =INPUT_DATA!A29 -> B8 | E29: =IFERROR(INDEX(FlowRates_kgs,MATCH(D29,LineTags,0)),"") -> 35.55 | F29: =IFERROR(INDEX(Densities,MATCH(D29,LineTags,0)),"") -> 1041.23 | G29: 0.3 | H29: =IFERROR(SQRT((4*E29)/(PI()*F29*G29))*1000,"") -> 380.6632 | I29: =IFERROR(VLOOKUP(ROUNDUP(H29,-1),PipeReference,2,TRUE),"Check Size") -> 428.6 | J29: =IFERROR((4*E29)/(PI()*F29*(I29/1000)^2),"") -> 0.23664575
A30: =A29+1 -> 26 | B30: ID800-8THK-SS-BW-09 | C30: Brine | D30: =INPUT_DATA!A30 -> B9 | E30: =IFERROR(INDEX(FlowRates_kgs,MATCH(D30,LineTags,0)),"") -> 39.83 | F30: =IFERROR(INDEX(Densities,MATCH(D30,LineTags,0)),"") -> 1041.51 | G30: 0.08 | H30: =IFERROR(SQRT((4*E30)/(PI()*F30*G30))*1000,"") -> 780.15967 | I30: =IFERROR(VLOOKUP(ROUNDUP(H30,-1),PipeReference,2,TRUE),"Check Size") -> Plate | J30: =IFERROR((4*E30)/(PI()*F30*(I30/1000)^2),"")
A31: =A30+1 -> 27 | B31: ID800-8THK-SS-BW-10 | C31: Brine | D31: =INPUT_DATA!A31 -> B10 | E31: =IFERROR(INDEX(FlowRates_kgs,MATCH(D31,LineTags,0)),"") -> 39.833514 | F31: =IFERROR(INDEX(Densities,MATCH(D31,LineTags,0)),"") -> 1039.7242 | G31: 0.08 | H31: =IFERROR(SQRT((4*E31)/(PI()*F31*G31))*1000,"") -> 780.86383 | I31: =IFERROR(VLOOKUP(ROUNDUP(H31,-1),PipeReference,2,TRUE),"Check Size") -> Plate | J31: =IFERROR((4*E31)/(PI()*F31*(I31/1000)^2),"")
A32: =A31+1 -> 28 | B32: XX-XX-SS-BW-11 | C32: Brine | D32: =INPUT_DATA!A32 -> B11 | E32: =IFERROR(INDEX(FlowRates_kgs,MATCH(D32,LineTags,0)),"") -> HOLD | F32: =IFERROR(INDEX(Densities,MATCH(D32,LineTags,0)),"") -> 1040.3579 | H32: =IFERROR(SQRT((4*E32)/(PI()*F32*G32))*1000,"") | I32: =IFERROR(VLOOKUP(ROUNDUP(H32,-1),PipeReference,2,TRUE),"Check Size") -> Check Size | J32: =IFERROR((4*E32)/(PI()*F32*(I32/1000)^2),"")
A33: =A32+1 -> 29 | B33: 200-40-SS-BW-12 | C33: Brine | D33: =INPUT_DATA!A33 -> B12 | E33: =IFERROR(INDEX(FlowRates_kgs,MATCH(D33,LineTags,0)),"") -> HOLD | F33: =IFERROR(INDEX(Densities,MATCH(D33,LineTags,0)),"") -> 1040.3579 | G33: 1 | H33: =IFERROR(SQRT((4*E33)/(PI()*F33*G33))*1000,"") | I33: =IFERROR(VLOOKUP(ROUNDUP(H33,-1),PipeReference,2,TRUE),"Check Size") -> Check Size | J33: =IFERROR((4*E33)/(PI()*F33*(I33/1000)^2),"")
A34: =A33+1 -> 30 | B34: 150-40-SS-BW-13 | C34: Brine | D34: =INPUT_DATA!A34 -> B13 | E34: =IFERROR(INDEX(FlowRates_kgs,MATCH(D34,LineTags,0)),"") -> 18.925 | F34: =IFERROR(INDEX(Densities,MATCH(D34,LineTags,0)),"") -> 1040.3579 | G34: 1.5 | H34: =IFERROR(SQRT((4*E34)/(PI()*F34*G34))*1000,"") -> 124.26133 | I34: =IFERROR(VLOOKUP(ROUNDUP(H34,-1),PipeReference,2,TRUE),"Check Size") -> 154.08 | J34: =IFERROR((4*E34)/(PI()*F34*(I34/1000)^2),"") -> 0.97559755
A35: =A34+1 -> 31 | B35: 150-40-SS-BW-14 | C35: Brine | D35: =INPUT_DATA!A35 -> B14 | E35: =IFERROR(INDEX(FlowRates_kgs,MATCH(D35,LineTags,0)),"") -> 18.925 | F35: =IFERROR(INDEX(Densities,MATCH(D35,LineTags,0)),"") -> 1040.3579 | G35: 1.5 | H35: =IFERROR(SQRT((4*E35)/(PI()*F35*G35))*1000,"") -> 124.26133 | I35: =IFERROR(VLOOKUP(ROUNDUP(H35,-1),PipeReference,2,TRUE),"Check Size") -> 154.08 | J35: =IFERROR((4*E35)/(PI()*F35*(I35/1000)^2),"") -> 0.97559755
A36: =A35+1 -> 32 | B36: 80-40-SS-BW-15 | C36: Brine | D36: =INPUT_DATA!A36 -> B15 | E36: =IFERROR(INDEX(FlowRates_kgs,MATCH(D36,LineTags,0)),"") -> 1.84 | F36: =IFERROR(INDEX(Densities,MATCH(D36,LineTags,0)),"") -> 1040.3579 | G36: 0.5 | H36: =IFERROR(SQRT((4*E36)/(PI()*F36*G36))*1000,"") -> 67.110054 | I36: =IFERROR(VLOOKUP(ROUNDUP(H36,-1),PipeReference,2,TRUE),"Check Size") -> 77.92 | J36: =IFERROR((4*E36)/(PI()*F36*(I36/1000)^2),"") -> 0.37089185
A37: =A36+1 -> 33 | B37: 80-40-SS-BW-16 | C37: Brine | D37: =INPUT_DATA!A37 -> B16 | E37: =IFERROR(INDEX(FlowRates_kgs,MATCH(D37,LineTags,0)),"") -> 1.84 | F37: =IFERROR(INDEX(Densities,MATCH(D37,LineTags,0)),"") -> 1040.3579 | G37: 0.5 | H37: =IFERROR(SQRT((4*E37)/(PI()*F37*G37))*1000,"") -> 67.110054 | I37: =IFERROR(VLOOKUP(ROUNDUP(H37,-1),PipeReference,2,TRUE),"Check Size") -> 77.92 | J37: =IFERROR((4*E37)/(PI()*F37*(I37/1000)^2),"") -> 0.37089185
A38: =A37+1 -> 34 | B38: 80-40-SS-BW-17 | C38: Brine | D38: =INPUT_DATA!A38 -> B17 | E38: =IFERROR(INDEX(FlowRates_kgs,MATCH(D38,LineTags,0)),"") -> 1.83 | F38: =IFERROR(INDEX(Densities,MATCH(D38,LineTags,0)),"") -> 1040.3579 | G38: 0.5 | H38: =IFERROR(SQRT((4*E38)/(PI()*F38*G38))*1000,"") -> 66.927441 | I38: =IFERROR(VLOOKUP(ROUNDUP(H38,-1),PipeReference,2,TRUE),"Check Size") -> 77.92 | J38: =IFERROR((4*E38)/(PI()*F38*(I38/1000)^2),"") -> 0.36887613
A39: =A38+1 -> 35 | B39: 80-40-SS-BW-18 | C39: Brine | D39: =INPUT_DATA!A39 -> B18 | E39: =IFERROR(INDEX(FlowRates_kgs,MATCH(D39,LineTags,0)),"") -> 2.31 | F39: =IFERROR(INDEX(Densities,MATCH(D39,LineTags,0)),"") -> 1040.3579 | G39: 0.7 | H39: =IFERROR(SQRT((4*E39)/(PI()*F39*G39))*1000,"") -> 63.550745 | I39: =IFERROR(VLOOKUP(ROUNDUP(H39,-1),PipeReference,2,TRUE),"Check Size") -> 77.92 | J39: =IFERROR((4*E39)/(PI()*F39*(I39/1000)^2),"") -> 0.46563053
A40: =A39+1 -> 36 | B40: 80-40-SS-BW-19 | C40: Brine | D40: =INPUT_DATA!A40 -> B19 | E40: =IFERROR(INDEX(FlowRates_kgs,MATCH(D40,LineTags,0)),"") -> 2.31 | F40: =IFERROR(INDEX(Densities,MATCH(D40,LineTags,0)),"") -> 1040.3579 | G40: 0.7 | H40: =IFERROR(SQRT((4*E40)/(PI()*F40*G40))*1000,"") -> 63.550745 | I40: =IFERROR(VLOOKUP(ROUNDUP(H40,-1),PipeReference,2,TRUE),"Check Size") -> 77.92 | J40: =IFERROR((4*E40)/(PI()*F40*(I40/1000)^2),"") -> 0.46563053
A41: =A40+1 -> 37 | B41: 80-40-SS-BW-20 | C41: Brine | D41: =INPUT_DATA!A41 -> B20 | E41: =IFERROR(INDEX(FlowRates_kgs,MATCH(D41,LineTags,0)),"") -> 2.31 | F41: =IFERROR(INDEX(Densities,MATCH(D41,LineTags,0)),"") -> 1040.3579 | G41: 0.7 | H41: =IFERROR(SQRT((4*E41)/(PI()*F41*G41))*1000,"") -> 63.550745 | I41: =IFERROR(VLOOKUP(ROUNDUP(H41,-1),PipeReference,2,TRUE),"Check Size") -> 77.92 | J41: =IFERROR((4*E41)/(PI()*F41*(I41/1000)^2),"") -> 0.46563053
A42: =A41+1 -> 38 | B42: 80-40-SS-BW-21 | C42: Brine | D42: =INPUT_DATA!A42 -> B21 | E42: =IFERROR(INDEX(FlowRates_kgs,MATCH(D42,LineTags,0)),"") -> 2.16 | F42: =IFERROR(INDEX(Densities,MATCH(D42,LineTags,0)),"") -> 1040.3579 | G42: 0.7 | H42: =IFERROR(SQRT((4*E42)/(PI()*F42*G42))*1000,"") -> 61.45278 | I42: =IFERROR(VLOOKUP(ROUNDUP(H42,-1),PipeReference,2,TRUE),"Check Size") -> 77.92 | J42: =IFERROR((4*E42)/(PI()*F42*(I42/1000)^2),"") -> 0.43539478
A43: =A42+1 -> 39 | B43: 80-40-SS-BW-22 | C43: Brine | D43: =INPUT_DATA!A43 -> B22 | E43: =IFERROR(INDEX(FlowRates_kgs,MATCH(D43,LineTags,0)),"") -> 2.16 | F43: =IFERROR(INDEX(Densities,MATCH(D43,LineTags,0)),"") -> 1040.3579 | G43: 0.7 | H43: =IFERROR(SQRT((4*E43)/(PI()*F43*G43))*1000,"") -> 61.45278 | I43: =IFERROR(VLOOKUP(ROUNDUP(H43,-1),PipeReference,2,TRUE),"Check Size") -> 77.92 | J43: =IFERROR((4*E43)/(PI()*F43*(I43/1000)^2),"") -> 0.43539478
...

Sheet LIST OF INSTRUMENTS
A1: S.No | B1: P&ID No | C1: Line No. | D1: TAG NO. | E1: INSTRUMENT VALVE No. | F1: SERVICE LOCATION | G1: INSTRUMENT TYPE | H1: Fluid | I1: Operation Condition | U1: Instrument data | AA1: Reference Hookup Diagram | AB1: Signal Type & Location | AE1: Instrument Model No | AF1: Accessories (Monifold/ TE/TW, etc,) | AG1: Remarks
I2: Pressure (m bar (a)) | L2: Temperature (Deg C) | O2: Flow rate (kg/hr) | R2: TDS (ppm) | U2: Inst. Range | V2: Type | W2: End connection | X2: MOC | Y2: Installation | Z2: Accessories | AB2: Local | AC2: PLC | AD2: I/O Type
I3: Min. | J3: Nor. | K3: Max. | L3: Min. | M3: Nor. | N3: Max. | O3: Min. | P3: Nor. | Q3: Max. | R3: Min. | S3: Nor. | T3: Max.
A4: 1 | B4: SP40-01-03-001 | C4: ='LIST OF LINES'!B4 -> 200-40-SS-SW-01 | D4: PIT-101 | E4: IV-101 | F4: Suction Side - Sea water pump skid | G4: Pressure Indicating Transmitter | H4: Sea water | J4: =IFERROR(INDEX(Pressures_mbar,MATCH(INDEX(LOL_LineTags,MATCH(C4,LOL_LineNumbers,0)),LineTags,0)),IFERROR(INDEX(LOE_Pressures,MATCH(C4,LOE_EquipNames,0)),INDEX(LOE_Pressures,MATCH(C4,LOE_EquipTags,0)))) -> 1000 | M4: =IFERROR(INDEX(Temperatures,MATCH(INDEX(LOL_LineTags,MATCH(C4,LOL_LineNumbers,0)),LineTags,0)),IFERROR(INDEX(LOE_Temperatures,MATCH(C4,LOE_EquipNames,0)),INDEX(LOE_Temperatures,MATCH(C4,LOE_EquipTags,0)))) -> 30 | P4: =IFERROR(INDEX(FlowRates_kghr,MATCH(INDEX(LOL_LineTags,MATCH(C4,LOL_LineNumbers,0)),LineTags,0)),"") -> 115522.21 | S4: =IFERROR(INDEX(TDS_Values,MATCH(INDEX(LOL_LineTags,MATCH(C4,LOL_LineNumbers,0)),LineTags,0)),"") -> 39504.432
A5: =A4+1 -> 2 | B5: SP40-01-03-001 | C5: ='LIST OF LINES'!$B$5 -> 200-40-SS-SW-02 | D5: PG-101 | E5: IV-102 | F5: Sea water pump-1 discharge pressure | G5: Pressure Gauge | H5: Sea water | J5: =IFERROR(INDEX(Pressures_mbar,MATCH(INDEX(LOL_LineTags,MATCH(C5,LOL_LineNumbers,0)),LineTags,0)),IFERROR(INDEX(LOE_Pressures,MATCH(C5,LOE_EquipNames,0)),INDEX(LOE_Pressures,MATCH(C5,LOE_EquipTags,0)))) -> 3500 | M5: =IFERROR(INDEX(Temperatures,MATCH(INDEX(LOL_LineTags,MATCH(C5,LOL_LineNumbers,0)),LineTags,0)),IFERROR(INDEX(LOE_Temperatures,MATCH(C5,LOE_EquipNames,0)),INDEX(LOE_Temperatures,MATCH(C5,LOE_EquipTags,0)))) -> 30.086198 | P5: =IFERROR(INDEX(FlowRates_kghr,MATCH(INDEX(LOL_LineTags,MATCH(C5,LOL_LineNumbers,0)),LineTags,0)),"") -> 115522.21 | S5: =IFERROR(INDEX(TDS_Values,MATCH(INDEX(LOL_LineTags,MATCH(C5,LOL_LineNumbers,0)),LineTags,0)),"") -> 39504.432
A6: =A5+1 -> 3 | B6: SP40-01-03-001 | C6: ='LIST OF LINES'!$B$5 -> 200-40-SS-SW-02 | D6: PG-102 | E6: IV-103 | F6: Discharge Side - Sea water pump-2 | G6: Pressure Gauge | H6: Sea water | J6: =IFERROR(INDEX(Pressures_mbar,MATCH(INDEX(LOL_LineTags,MATCH(C6,LOL_LineNumbers,0)),LineTags,0)),IFERROR(INDEX(LOE_Pressures,MATCH(C6,LOE_EquipNames,0)),INDEX(LOE_Pressures,MATCH(C6,LOE_EquipTags,0)))) -> 3500 | M6: =IFERROR(INDEX(Temperatures,MATCH(INDEX(LOL_LineTags,MATCH(C6,LOL_LineNumbers,0)),LineTags,0)),IFERROR(INDEX(LOE_Temperatures,MATCH(C6,LOE_EquipNames,0)),INDEX(LOE_Temperatures,MATCH(C6,LOE_EquipTags,0)))) -> 30.086198 | P6: =IFERROR(INDEX(FlowRates_kghr,MATCH(INDEX(LOL_LineTags,MATCH(C6,LOL_LineNumbers,0)),LineTags,0)),"") -> 115522.21 | S6: =IFERROR(INDEX(TDS_Values,MATCH(INDEX(LOL_LineTags,MATCH(C6,LOL_LineNumbers,0)),LineTags,0)),"") -> 39504.432
A7: =A6+1 -> 4 | B7: SP40-01-03-001 | C7: ='LIST OF LINES'!$B$5 -> 200-40-SS-SW-02 | D7: PSL-101 | E7: IV-104 | F7: Discharge Side - Sea water pump | G7: Pressure Switch | H7: Sea water | J7: =IFERROR(INDEX(Pressures_mbar,MATCH(INDEX(LOL_LineTags,MATCH(C7,LOL_LineNumbers,0)),LineTags,0)),IFERROR(INDEX(LOE_Pressures,MATCH(C7,LOE_EquipNames,0)),INDEX(LOE_Pressures,MATCH(C7,LOE_EquipTags,0)))) -> 3500 | M7: =IFERROR(INDEX(Temperatures,MATCH(INDEX(LOL_LineTags,MATCH(C7,LOL_LineNumbers,0)),LineTags,0)),IFERROR(INDEX(LOE_Temperatures,MATCH(C7,LOE_EquipNames,0)),INDEX(LOE_Temperatures,MATCH(C7,LOE_EquipTags,0)))) -> 30.086198 | P7: =IFERROR(INDEX(FlowRates_kghr,MATCH(INDEX(LOL_LineTags,MATCH(C7,LOL_LineNumbers,0)),LineTags,0)),"") -> 115522.21 | S7: =IFERROR(INDEX(TDS_Values,MATCH(INDEX(LOL_LineTags,MATCH(C7,LOL_LineNumbers,0)),LineTags,0)),"") -> 39504.432
A8: =A7+1 -> 5 | B8: SP40-01-03-001 | C8: ='LIST OF LINES'!$B$5 -> 200-40-SS-SW-02 | D8: PIT-102 | E8: IV-105 | F8: Discharge Side - Sea water pump skid | G8: Pressure Indicating Transmitter | H8: Sea water | J8: =IFERROR(INDEX(Pressures_mbar,MATCH(INDEX(LOL_LineTags,MATCH(C8,LOL_LineNumbers,0)),LineTags,0)),IFERROR(INDEX(LOE_Pressures,MATCH(C8,LOE_EquipNames,0)),INDEX(LOE_Pressures,MATCH(C8,LOE_EquipTags,0)))) -> 3500 | M8: =IFERROR(INDEX(Temperatures,MATCH(INDEX(LOL_LineTags,MATCH(C8,LOL_LineNumbers,0)),LineTags,0)),IFERROR(INDEX(LOE_Temperatures,MATCH(C8,LOE_EquipNames,0)),INDEX(LOE_Temperatures,MATCH(C8,LOE_EquipTags,0)))) -> 30.086198 | P8: =IFERROR(INDEX(FlowRates_kghr,MATCH(INDEX(LOL_LineTags,MATCH(C8,LOL_LineNumbers,0)),LineTags,0)),"") -> 115522.21 | S8: =IFERROR(INDEX(TDS_Values,MATCH(INDEX(LOL_LineTags,MATCH(C8,LOL_LineNumbers,0)),LineTags,0)),"") -> 39504.432
A9: =A8+1 -> 6 | B9: SP40-01-03-001 | C9: ='LIST OF LINES'!$B$5 -> 200-40-SS-SW-02 | D9: TE-101 | F9: Delivery Side - Sea water pump | G9: Temperature Element with TW | H9: Sea water | J9: =IFERROR(INDEX(Pressures_mbar,MATCH(INDEX(LOL_LineTags,MATCH(C9,LOL_LineNumbers,0)),LineTags,0)),IFERROR(INDEX(LOE_Pressures,MATCH(C9,LOE_EquipNames,0)),INDEX(LOE_Pressures,MATCH(C9,LOE_EquipTags,0)))) -> 3500 | M9: =IFERROR(INDEX(Temperatures,MATCH(INDEX(LOL_LineTags,MATCH(C9,LOL_LineNumbers,0)),LineTags,0)),IFERROR(INDEX(LOE_Temperatures,MATCH(C9,LOE_EquipNames,0)),INDEX(LOE_Temperatures,MATCH(C9,LOE_EquipTags,0)))) -> 30.086198 | P9: =IFERROR(INDEX(FlowRates_kghr,MATCH(INDEX(LOL_LineTags,MATCH(C9,LOL_LineNumbers,0)),LineTags,0)),"") -> 115522.21 | S9: =IFERROR(INDEX(TDS_Values,MATCH(INDEX(LOL_LineTags,MATCH(C9,LOL_LineNumbers,0)),LineTags,0)),"") -> 39504.432
A10: =A9+1 -> 7 | B10: SP40-01-03-001 | C10: ='LIST OF LINES'!$B$5 -> 200-40-SS-SW-02 | D10: TIT-101 | F10: Delivery Side - Sea water pump skid | G10: Temperature Indicating Transmitter | H10: Sea water | J10: =IFERROR(INDEX(Pressures_mbar,MATCH(INDEX(LOL_LineTags,MATCH(C10,LOL_LineNumbers,0)),LineTags,0)),IFERROR(INDEX(LOE_Pressures,MATCH(C10,LOE_EquipNames,0)),INDEX(LOE_Pressures,MATCH(C10,LOE_EquipTags,0)))) -> 3500 | M10: =IFERROR(INDEX(Temperatures,MATCH(INDEX(LOL_LineTags,MATCH(C10,LOL_LineNumbers,0)),LineTags,0)),IFERROR(INDEX(LOE_Temperatures,MATCH(C10,LOE_EquipNames,0)),INDEX(LOE_Temperatures,MATCH(C10,LOE_EquipTags,0)))) -> 30.086198 | P10: =IFERROR(INDEX(FlowRates_kghr,MATCH(INDEX(LOL_LineTags,MATCH(C10,LOL_LineNumbers,0)),LineTags,0)),"") -> 115522.21 | S10: =IFERROR(INDEX(TDS_Values,MATCH(INDEX(LOL_LineTags,MATCH(C10,LOL_LineNumbers,0)),LineTags,0)),"") -> 39504.432
A11: =A10+1 -> 8 | B11: SP40-01-03-001 | C11: ='LIST OF LINES'!$B$5 -> 200-40-SS-SW-02 | D11: FIT-110 | F11: Delivery Side - Sea water pump skid | G11: Electro Magnetic Flow meter | H11: Sea water | J11: =IFERROR(INDEX(Pressures_mbar,MATCH(INDEX(LOL_LineTags,MATCH(C11,LOL_LineNumbers,0)),LineTags,0)),IFERROR(INDEX(LOE_Pressures,MATCH(C11,LOE_EquipNames,0)),INDEX(LOE_Pressures,MATCH(C11,LOE_EquipTags,0)))) -> 3500 | M11: =IFERROR(INDEX(Temperatures,MATCH(INDEX(LOL_LineTags,MATCH(C11,LOL_LineNumbers,0)),LineTags,0)),IFERROR(INDEX(LOE_Temperatures,MATCH(C11,LOE_EquipNames,0)),INDEX(LOE_Temperatures,MATCH(C11,LOE_EquipTags,0)))) -> 30.086198 | P11: =IFERROR(INDEX(FlowRates_kghr,MATCH(INDEX(LOL_LineTags,MATCH(C11,LOL_LineNumbers,0)),LineTags,0)),"") -> 115522.21 | S11: =IFERROR(INDEX(TDS_Values,MATCH(INDEX(LOL_LineTags,MATCH(C11,LOL_LineNumbers,0)),LineTags,0)),"") -> 39504.432
A12: =A11+1 -> 9 | B12: SP40-01-03-001 | C12: ='LIST OF LINES'!$B$5 -> 200-40-SS-SW-02 | D12: CIT-101 | E12: IV-109 | F12: Delivery Side - Sea water pump skid | G12: Conductivity Transmitter | H12: Sea water | J12: =IFERROR(INDEX(Pressures_mbar,MATCH(INDEX(LOL_LineTags,MATCH(C12,LOL_LineNumbers,0)),LineTags,0)),IFERROR(INDEX(LOE_Pressures,MATCH(C12,LOE_EquipNames,0)),INDEX(LOE_Pressures,MATCH(C12,LOE_EquipTags,0)))) -> 3500 | M12: =IFERROR(INDEX(Temperatures,MATCH(INDEX(LOL_LineTags,MATCH(C12,LOL_LineNumbers,0)),LineTags,0)),IFERROR(INDEX(LOE_Temperatures,MATCH(C12,LOE_EquipNames,0)),INDEX(LOE_Temperatures,MATCH(C12,LOE_EquipTags,0)))) -> 30.086198 | P12: =IFERROR(INDEX(FlowRates_kghr,MATCH(INDEX(LOL_LineTags,MATCH(C12,LOL_LineNumbers,0)),LineTags,0)),"") -> 115522.21 | S12: =IFERROR(INDEX(TDS_Values,MATCH(INDEX(LOL_LineTags,MATCH(C12,LOL_LineNumbers,0)),LineTags,0)),"") -> 39504.432
A13: =A12+1 -> 10 | B13: SP40-01-03-001 | C13: ='LIST OF LINES'!$B$7 -> 100-40-SS-SW-04 | D13: PIT-103 | E13: IV-106 | F13: Distillate Plate Heat Exchanger - Outlet | G13: Pressure Indicating Transmitter | H13: Sea water | J13: =IFERROR(INDEX(Pressures_mbar,MATCH(INDEX(LOL_LineTags,MATCH(C13,LOL_LineNumbers,0)),LineTags,0)),IFERROR(INDEX(LOE_Pressures,MATCH(C13,LOE_EquipNames,0)),INDEX(LOE_Pressures,MATCH(C13,LOE_EquipTags,0)))) -> 3500 | M13: =IFERROR(INDEX(Temperatures,MATCH(INDEX(LOL_LineTags,MATCH(C13,LOL_LineNumbers,0)),LineTags,0)),IFERROR(INDEX(LOE_Temperatures,MATCH(C13,LOE_EquipNames,0)),INDEX(LOE_Temperatures,MATCH(C13,LOE_EquipTags,0)))) -> 36 | P13: =IFERROR(INDEX(FlowRates_kghr,MATCH(INDEX(LOL_LineTags,MATCH(C13,LOL_LineNumbers,0)),LineTags,0)),"") -> 40282.214 | S13: =IFERROR(INDEX(TDS_Values,MATCH(INDEX(LOL_LineTags,MATCH(C13,LOL_LineNumbers,0)),LineTags,0)),"") -> 39504.432
A14: =A13+1 -> 11 | B14: SP40-01-03-001 | C14: ='LIST OF LINES'!$B$7 -> 100-40-SS-SW-04 | D14: TE-102 | F14: Distillate Plate Heat Exchanger - Outlet | G14: Temperature Element with TW | H14: Sea water | J14: =IFERROR(INDEX(Pressures_mbar,MATCH(INDEX(LOL_LineTags,MATCH(C14,LOL_LineNumbers,0)),LineTags,0)),IFERROR(INDEX(LOE_Pressures,MATCH(C14,LOE_EquipNames,0)),INDEX(LOE_Pressures,MATCH(C14,LOE_EquipTags,0)))) -> 3500 | M14: =IFERROR(INDEX(Temperatures,MATCH(INDEX(LOL_LineTags,MATCH(C14,LOL_LineNumbers,0)),LineTags,0)),IFERROR(INDEX(LOE_Temperatures,MATCH(C14,LOE_EquipNames,0)),INDEX(LOE_Temperatures,MATCH(C14,LOE_EquipTags,0)))) -> 36 | P14: =IFERROR(INDEX(FlowRates_kghr,MATCH(INDEX(LOL_LineTags,MATCH(C14,LOL_LineNumbers,0)),LineTags,0)),"") -> 40282.214 | S14: =IFERROR(INDEX(TDS_Values,MATCH(INDEX(LOL_LineTags,MATCH(C14,LOL_LineNumbers,0)),LineTags,0)),"") -> 39504.432
A15: =A14+1 -> 12 | B15: SP40-01-03-001 | C15: ='LIST OF LINES'!$B$7 -> 100-40-SS-SW-04 | D15: TIT-102 | F15: Distillate Plate Heat Exchanger - Outlet | G15: Temperature Indicating Transmitter | H15: Sea water | J15: =IFERROR(INDEX(Pressures_mbar,MATCH(INDEX(LOL_LineTags,MATCH(C15,LOL_LineNumbers,0)),LineTags,0)),IFERROR(INDEX(LOE_Pressures,MATCH(C15,LOE_EquipNames,0)),INDEX(LOE_Pressures,MATCH(C15,LOE_EquipTags,0)))) -> 3500 | M15: =IFERROR(INDEX(Temperatures,MATCH(INDEX(LOL_LineTags,MATCH(C15,LOL_LineNumbers,0)),LineTags,0)),IFERROR(INDEX(LOE_Temperatures,MATCH(C15,LOE_EquipNames,0)),INDEX(LOE_Temperatures,MATCH(C15,LOE_EquipTags,0)))) -> 36 | P15: =IFERROR(INDEX(FlowRates_kghr,MATCH(INDEX(LOL_LineTags,MATCH(C15,LOL_LineNumbers,0)),LineTags,0)),"") -> 40282.214 | S15: =IFERROR(INDEX(TDS_Values,MATCH(INDEX(LOL_LineTags,MATCH(C15,LOL_LineNumbers,0)),LineTags,0)),"") -> 39504.432
A16: =A15+1 -> 13 | B16: SP40-01-03-002 | C16: ='LIST OF LINES'!B8 -> 65-40-SS-SW-05 | D16: ZT-101 | F16: MED - 1st effect | G16: Position Transmitter | H16: Sea water | J16: =IFERROR(INDEX(Pressures_mbar,MATCH(INDEX(LOL_LineTags,MATCH(C16,LOL_LineNumbers,0)),LineTags,0)),IFERROR(INDEX(LOE_Pressures,MATCH(C16,LOE_EquipNames,0)),INDEX(LOE_Pressures,MATCH(C16,LOE_EquipTags,0)))) -> 3500 | M16: =IFERROR(INDEX(Temperatures,MATCH(INDEX(LOL_LineTags,MATCH(C16,LOL_LineNumbers,0)),LineTags,0)),IFERROR(INDEX(LOE_Temperatures,MATCH(C16,LOE_EquipNames,0)),INDEX(LOE_Temperatures,MATCH(C16,LOE_EquipTags,0)))) -> 36 | P16: =IFERROR(INDEX(FlowRates_kghr,MATCH(INDEX(LOL_LineTags,MATCH(C16,LOL_LineNumbers,0)),LineTags,0)),"") -> 13427.405 | S16: =IFERROR(INDEX(TDS_Values,MATCH(INDEX(LOL_LineTags,MATCH(C16,LOL_LineNumbers,0)),LineTags,0)),"") -> 39504.432
A17: =A16+1 -> 14 | B17: SP40-01-03-002 | C17: ='LIST OF LINES'!B8 -> 65-40-SS-SW-05 | D17: FIT-101 | F17: MED - 1st effect sea water flow | G17: Electro Magnetic Flow meter | H17: Sea water | J17: =IFERROR(INDEX(Pressures_mbar,MATCH(INDEX(LOL_LineTags,MATCH(C17,LOL_LineNumbers,0)),LineTags,0)),IFERROR(INDEX(LOE_Pressures,MATCH(C17,LOE_EquipNames,0)),INDEX(LOE_Pressures,MATCH(C17,LOE_EquipTags,0)))) -> 3500 | M17: =IFERROR(INDEX(Temperatures,MATCH(INDEX(LOL_LineTags,MATCH(C17,LOL_LineNumbers,0)),LineTags,0)),IFERROR(INDEX(LOE_Temperatures,MATCH(C17,LOE_EquipNames,0)),INDEX(LOE_Temperatures,MATCH(C17,LOE_EquipTags,0)))) -> 36 | P17: =IFERROR(INDEX(FlowRates_kghr,MATCH(INDEX(LOL_LineTags,MATCH(C17,LOL_LineNumbers,0)),LineTags,0)),"") -> 13427.405 | S17: =IFERROR(INDEX(TDS_Values,MATCH(INDEX(LOL_LineTags,MATCH(C17,LOL_LineNumbers,0)),LineTags,0)),"") -> 39504.432
A18: =A17+1 -> 15 | B18: SP40-01-03-002 | C18: ='LIST OF LINES'!B9 -> 65-40-SS-SW-06 | D18: ZT-102 | F18: MED - 2nd effect | G18: Position Transmitter | H18: Sea water | J18: =IFERROR(INDEX(Pressures_mbar,MATCH(INDEX(LOL_LineTags,MATCH(C18,LOL_LineNumbers,0)),LineTags,0)),IFERROR(INDEX(LOE_Pressures,MATCH(C18,LOE_EquipNames,0)),INDEX(LOE_Pressures,MATCH(C18,LOE_EquipTags,0)))) -> 3500 | M18: =IFERROR(INDEX(Temperatures,MATCH(INDEX(LOL_LineTags,MATCH(C18,LOL_LineNumbers,0)),LineTags,0)),IFERROR(INDEX(LOE_Temperatures,MATCH(C18,LOE_EquipNames,0)),INDEX(LOE_Temperatures,MATCH(C18,LOE_EquipTags,0)))) -> 36 | P18: =IFERROR(INDEX(FlowRates_kghr,MATCH(INDEX(LOL_LineTags,MATCH(C18,LOL_LineNumbers,0)),LineTags,0)),"") -> 13427.405 | S18: =IFERROR(INDEX(TDS_Values,MATCH(INDEX(LOL_LineTags,MATCH(C18,LOL_LineNumbers,0)),LineTags,0)),"") -> 39504.432
A19: =A18+1 -> 16 | B19: SP40-01-03-002 | C19: ='LIST OF LINES'!B9 -> 65-40-SS-SW-06 | D19: FIT-102 | F19: MED - 2nd effect sea water flow | G19: Electro Magnetic Flow meter | H19: Sea water | J19: =IFERROR(INDEX(Pressures_mbar,MATCH(INDEX(LOL_LineTags,MATCH(C19,LOL_LineNumbers,0)),LineTags,0)),IFERROR(INDEX(LOE_Pressures,MATCH(C19,LOE_EquipNames,0)),INDEX(LOE_Pressures,MATCH(C19,LOE_EquipTags,0)))) -> 3500 | M19: =IFERROR(INDEX(Temperatures,MATCH(INDEX(LOL_LineTags,MATCH(C19,LOL_LineNumbers,0)),LineTags,0)),IFERROR(INDEX(LOE_Temperatures,MATCH(C19,LOE_EquipNames,0)),INDEX(LOE_Temperatures,MATCH(C19,LOE_EquipTags,0)))) -> 36 | P19: =IFERROR(INDEX(FlowRates_kghr,MATCH(INDEX(LOL_LineTags,MATCH(C19,LOL_LineNumbers,0)),LineTags,0)),"") -> 13427.405 | S19: =IFERROR(INDEX(TDS_Values,MATCH(INDEX(LOL_LineTags,MATCH(C19,LOL_LineNumbers,0)),LineTags,0)),"") -> 39504.432
A20: =A19+1 -> 17 | B20: SP40-01-03-002 | C20: ='LIST OF LINES'!B10 -> 65-40-SS-SW-07 | D20: ZT-103 | F20: MED - 3rd effect | G20: Position Transmitter | H20: Sea water | J20: =IFERROR(INDEX(Pressures_mbar,MATCH(INDEX(LOL_LineTags,MATCH(C20,LOL_LineNumbers,0)),LineTags,0)),IFERROR(INDEX(LOE_Pressures,MATCH(C20,LOE_EquipNames,0)),INDEX(LOE_Pressures,MATCH(C20,LOE_EquipTags,0)))) -> 3500 | M20: =IFERROR(INDEX(Temperatures,MATCH(INDEX(LOL_LineTags,MATCH(C20,LOL_LineNumbers,0)),LineTags,0)),IFERROR(INDEX(LOE_Temperatures,MATCH(C20,LOE_EquipNames,0)),INDEX(LOE_Temperatures,MATCH(C20,LOE_EquipTags,0)))) -> 36 | P20: =IFERROR(INDEX(FlowRates_kghr,MATCH(INDEX(LOL_LineTags,MATCH(C20,LOL_LineNumbers,0)),LineTags,0)),"") -> 13427.405 | S20: =IFERROR(INDEX(TDS_Values,MATCH(INDEX(LOL_LineTags,MATCH(C20,LOL_LineNumbers,0)),LineTags,0)),"") -> 39504.432
A21: =A20+1 -> 18 | B21: SP40-01-03-002 | C21: ='LIST OF LINES'!B10 -> 65-40-SS-SW-07 | D21: FIT-103 | F21: MED - 3rd effect sea water flow | G21: Electro Magnetic Flow meter | H21: Sea water | J21: =IFERROR(INDEX(Pressures_mbar,MATCH(INDEX(LOL_LineTags,MATCH(C21,LOL_LineNumbers,0)),LineTags,0)),IFERROR(INDEX(LOE_Pressures,MATCH(C21,LOE_EquipNames,0)),INDEX(LOE_Pressures,MATCH(C21,LOE_EquipTags,0)))) -> 3500 | M21: =IFERROR(INDEX(Temperatures,MATCH(INDEX(LOL_LineTags,MATCH(C21,LOL_LineNumbers,0)),LineTags,0)),IFERROR(INDEX(LOE_Temperatures,MATCH(C21,LOE_EquipNames,0)),INDEX(LOE_Temperatures,MATCH(C21,LOE_EquipTags,0)))) -> 36 | P21: =IFERROR(INDEX(FlowRates_kghr,MATCH(INDEX(LOL_LineTags,MATCH(C21,LOL_LineNumbers,0)),LineTags,0)),"") -> 13427.405 | S21: =IFERROR(INDEX(TDS_Values,MATCH(INDEX(LOL_LineTags,MATCH(C21,LOL_LineNumbers,0)),LineTags,0)),"") -> 39504.432
A22: =A21+1 -> 19 | B22: SP40-01-03-001 | C22: ='LIST OF LINES'!B12 -> 100-40-SS-SW-09 | D22: PIT-104 | E22: IV-107 | F22: Brine Plate Heat Exchanger - Outlet | G22: Pressure Indicating Transmitter | H22: Sea water | J22: =IFERROR(INDEX(Pressures_mbar,MATCH(INDEX(LOL_LineTags,MATCH(C22,LOL_LineNumbers,0)),LineTags,0)),IFERROR(INDEX(LOE_Pressures,MATCH(C22,LOE_EquipNames,0)),INDEX(LOE_Pressures,MATCH(C22,LOE_EquipTags,0)))) -> 3500 | M22: =IFERROR(INDEX(Temperatures,MATCH(INDEX(LOL_LineTags,MATCH(C22,LOL_LineNumbers,0)),LineTags,0)),IFERROR(INDEX(LOE_Temperatures,MATCH(C22,LOE_EquipNames,0)),INDEX(LOE_Temperatures,MATCH(C22,LOE_EquipTags,0)))) -> 36.45 | P22: =IFERROR(INDEX(FlowRates_kghr,MATCH(INDEX(LOL_LineTags,MATCH(C22,LOL_LineNumbers,0)),LineTags,0)),"") -> 35640 | S22: =IFERROR(INDEX(TDS_Values,MATCH(INDEX(LOL_LineTags,MATCH(C22,LOL_LineNumbers,0)),LineTags,0)),"") -> 39504.432
A23: =A22+1 -> 20 | B23: SP40-01-03-001 | C23: ='LIST OF LINES'!B12 -> 100-40-SS-SW-09 | D23: TE-103 | F23: Brine Plate Heat Exchanger - Outlet | G23: Temperature Element with TW | H23: Sea water | J23: =IFERROR(INDEX(Pressures_mbar,MATCH(INDEX(LOL_LineTags,MATCH(C23,LOL_LineNumbers,0)),LineTags,0)),IFERROR(INDEX(LOE_Pressures,MATCH(C23,LOE_EquipNames,0)),INDEX(LOE_Pressures,MATCH(C23,LOE_EquipTags,0)))) -> 3500 | M23: =IFERROR(INDEX(Temperatures,MATCH(INDEX(LOL_LineTags,MATCH(C23,LOL_LineNumbers,0)),LineTags,0)),IFERROR(INDEX(LOE_Temperatures,MATCH(C23,LOE_EquipNames,0)),INDEX(LOE_Temperatures,MATCH(C23,LOE_EquipTags,0)))) -> 36.45 | P23: =IFERROR(INDEX(FlowRates_kghr,MATCH(INDEX(LOL_LineTags,MATCH(C23,LOL_LineNumbers,0)),LineTags,0)),"") -> 35640 | S23: =IFERROR(INDEX(TDS_Values,MATCH(INDEX(LOL_LineTags,MATCH(C23,LOL_LineNumbers,0)),LineTags,0)),"") -> 39504.432
A24: =A23+1 -> 21 | B24: SP40-01-03-001 | C24: ='LIST OF LINES'!B12 -> 100-40-SS-SW-09 | D24: TIT-103 | F24: Brine Plate Heat Exchanger - Outlet | G24: Temperature Indicating Transmitter | H24: Sea water | J24: =IFERROR(INDEX(Pressures_mbar,MATCH(INDEX(LOL_LineTags,MATCH(C24,LOL_LineNumbers,0)),LineTags,0)),IFERROR(INDEX(LOE_Pressures,MATCH(C24,LOE_EquipNames,0)),INDEX(LOE_Pressures,MATCH(C24,LOE_EquipTags,0)))) -> 3500 | M24: =IFERROR(INDEX(Temperatures,MATCH(INDEX(LOL_LineTags,MATCH(C24,LOL_LineNumbers,0)),LineTags,0)),IFERROR(INDEX(LOE_Temperatures,MATCH(C24,LOE_EquipNames,0)),INDEX(LOE_Temperatures,MATCH(C24,LOE_EquipTags,0)))) -> 36.45 | P24: =IFERROR(INDEX(FlowRates_kghr,MATCH(INDEX(LOL_LineTags,MATCH(C24,LOL_LineNumbers,0)),LineTags,0)),"") -> 35640 | S24: =IFERROR(INDEX(TDS_Values,MATCH(INDEX(LOL_LineTags,MATCH(C24,LOL_LineNumbers,0)),LineTags,0)),"") -> 39504.432
A25: =A24+1 -> 22 | B25: SP40-01-03-002 | C25: ='LIST OF LINES'!B13 -> 65-40-SS-SW-10 | D25: ZT-104 | F25: MED - 4th effect | G25: Position Transmitter | H25: Sea water | J25: =IFERROR(INDEX(Pressures_mbar,MATCH(INDEX(LOL_LineTags,MATCH(C25,LOL_LineNumbers,0)),LineTags,0)),IFERROR(INDEX(LOE_Pressures,MATCH(C25,LOE_EquipNames,0)),INDEX(LOE_Pressures,MATCH(C25,LOE_EquipTags,0)))) -> 3500 | M25: =IFERROR(INDEX(Temperatures,MATCH(INDEX(LOL_LineTags,MATCH(C25,LOL_LineNumbers,0)),LineTags,0)),IFERROR(INDEX(LOE_Temperatures,MATCH(C25,LOE_EquipNames,0)),INDEX(LOE_Temperatures,MATCH(C25,LOE_EquipTags,0)))) -> 36.45 | P25: =IFERROR(INDEX(FlowRates_kghr,MATCH(INDEX(LOL_LineTags,MATCH(C25,LOL_LineNumbers,0)),LineTags,0)),"") -> 11880 | S25: =IFERROR(INDEX(TDS_Values,MATCH(INDEX(LOL_LineTags,MATCH(C25,LOL_LineNumbers,0)),LineTags,0)),"") -> 39504.432
A26: =A25+1 -> 23 | B26: SP40-01-03-002 | C26: ='LIST OF LINES'!B13 -> 65-40-SS-SW-10 | D26: FIT-104 | F26: MED - 4th effect sea water flow | G26: Electro Magnetic Flow meter | H26: Sea water | J26: =IFERROR(INDEX(Pressures_mbar,MATCH(INDEX(LOL_LineTags,MATCH(C26,LOL_LineNumbers,0)),LineTags,0)),IFERROR(INDEX(LOE_Pressures,MATCH(C26,LOE_EquipNames,0)),INDEX(LOE_Pressures,MATCH(C26,LOE_EquipTags,0)))) -> 3500 | M26: =IFERROR(INDEX(Temperatures,MATCH(INDEX(LOL_LineTags,MATCH(C26,LOL_LineNumbers,0)),LineTags,0)),IFERROR(INDEX(LOE_Temperatures,MATCH(C26,LOE_EquipNames,0)),INDEX(LOE_Temperatures,MATCH(C26,LOE_EquipTags,0)))) -> 36.45 | P26: =IFERROR(INDEX(FlowRates_kghr,MATCH(INDEX(LOL_LineTags,MATCH(C26,LOL_LineNumbers,0)),LineTags,0)),"") -> 11880 | S26: =IFERROR(INDEX(TDS_Values,MATCH(INDEX(LOL_LineTags,MATCH(C26,LOL_LineNumbers,0)),LineTags,0)),"") -> 39504.432
A27: =A26+1 -> 24 | B27: SP40-01-03-002 | C27: ='LIST OF LINES'!B14 -> 65-40-SS-SW-11 | D27: ZT-105 | F27: MED - 5th effect | G27: Position Transmitter | H27: Sea water | J27: =IFERROR(INDEX(Pressures_mbar,MATCH(INDEX(LOL_LineTags,MATCH(C27,LOL_LineNumbers,0)),LineTags,0)),IFERROR(INDEX(LOE_Pressures,MATCH(C27,LOE_EquipNames,0)),INDEX(LOE_Pressures,MATCH(C27,LOE_EquipTags,0)))) -> 3500 | M27: =IFERROR(INDEX(Temperatures,MATCH(INDEX(LOL_LineTags,MATCH(C27,LOL_LineNumbers,0)),LineTags,0)),IFERROR(INDEX(LOE_Temperatures,MATCH(C27,LOE_EquipNames,0)),INDEX(LOE_Temperatures,MATCH(C27,LOE_EquipTags,0)))) -> 36.45 | P27: =IFERROR(INDEX(FlowRates_kghr,MATCH(INDEX(LOL_LineTags,MATCH(C27,LOL_LineNumbers,0)),LineTags,0)),"") -> 11880 | S27: =IFERROR(INDEX(TDS_Values,MATCH(INDEX(LOL_LineTags,MATCH(C27,LOL_LineNumbers,0)),LineTags,0)),"") -> 39504.432
A28: =A27+1 -> 25 | B28: SP40-01-03-002 | C28: ='LIST OF LINES'!B14 -> 65-40-SS-SW-11 | D28: FIT-105 | F28: MED - 5th effect sea water flow | G28: Electro Magnetic Flow meter | H28: Sea water | J28: =IFERROR(INDEX(Pressures_mbar,MATCH(INDEX(LOL_LineTags,MATCH(C28,LOL_LineNumbers,0)),LineTags,0)),IFERROR(INDEX(LOE_Pressures,MATCH(C28,LOE_EquipNames,0)),INDEX(LOE_Pressures,MATCH(C28,LOE_EquipTags,0)))) -> 3500 | M28: =IFERROR(INDEX(Temperatures,MATCH(INDEX(LOL_LineTags,MATCH(C28,LOL_LineNumbers,0)),LineTags,0)),IFERROR(INDEX(LOE_Temperatures,MATCH(C28,LOE_EquipNames,0)),INDEX(LOE_Temperatures,MATCH(C28,LOE_EquipTags,0)))) -> 36.45 | P28: =IFERROR(INDEX(FlowRates_kghr,MATCH(INDEX(LOL_LineTags,MATCH(C28,LOL_LineNumbers,0)),LineTags,0)),"") -> 11880 | S28: =IFERROR(INDEX(TDS_Values,MATCH(INDEX(LOL_LineTags,MATCH(C28,LOL_LineNumbers,0)),LineTags,0)),"") -> 39504.432
A29: =A28+1 -> 26 | B29: SP40-01-03-002 | C29: ='LIST OF LINES'!B15 -> 65-40-SS-SW-12 | D29: ZT-106 | F29: MED - 6th effect | G29: Position Transmitter | H29: Sea water | J29: =IFERROR(INDEX(Pressures_mbar,MATCH(INDEX(LOL_LineTags,MATCH(C29,LOL_LineNumbers,0)),LineTags,0)),IFERROR(INDEX(LOE_Pressures,MATCH(C29,LOE_EquipNames,0)),INDEX(LOE_Pressures,MATCH(C29,LOE_EquipTags,0)))) -> 3500 | M29: =IFERROR(INDEX(Temperatures,MATCH(INDEX(LOL_LineTags,MATCH(C29,LOL_LineNumbers,0)),LineTags,0)),IFERROR(INDEX(LOE_Temperatures,MATCH(C29,LOE_EquipNames,0)),INDEX(LOE_Temperatures,MATCH(C29,LOE_EquipTags,0)))) -> 36.45 | P29: =IFERROR(INDEX(FlowRates_kghr,MATCH(INDEX(LOL_LineTags,MATCH(C29,LOL_LineNumbers,0)),LineTags,0)),"") -> 11880 | S29: =IFERROR(INDEX(TDS_Values,MATCH(INDEX(LOL_LineTags,MATCH(C29,LOL_LineNumbers,0)),LineTags,0)),"") -> 39504.432
A30: =A29+1 -> 27 | B30: SP40-01-03-002 | C30: ='LIST OF LINES'!B15 -> 65-40-SS-SW-12 | D30: FIT-106 | F30: MED - 6th effect sea water flow | G30: Electro Magnetic Flow meter | H30: Sea water | J30: =IFERROR(INDEX(Pressures_mbar,MATCH(INDEX(LOL_LineTags,MATCH(C30,LOL_LineNumbers,0)),LineTags,0)),IFERROR(INDEX(LOE_Pressures,MATCH(C30,LOE_EquipNames,0)),INDEX(LOE_Pressures,MATCH(C30,LOE_EquipTags,0)))) -> 3500 | M30: =IFERROR(INDEX(Temperatures,MATCH(INDEX(LOL_LineTags,MATCH(C30,LOL_LineNumbers,0)),LineTags,0)),IFERROR(INDEX(LOE_Temperatures,MATCH(C30,LOE_EquipNames,0)),INDEX(LOE_Temperatures,MATCH(C30,LOE_EquipTags,0)))) -> 36.45 | P30: =IFERROR(INDEX(FlowRates_kghr,MATCH(INDEX(LOL_LineTags,MATCH(C30,LOL_LineNumbers,0)),LineTags,0)),"") -> 11880 | S30: =IFERROR(INDEX(TDS_Values,MATCH(INDEX(LOL_LineTags,MATCH(C30,LOL_LineNumbers,0)),LineTags,0)),"") -> 39504.432
A31: =A30+1 -> 28 | B31: SP40-01-03-001 | C31: ='LIST OF LINES'!B17 -> 100-40-SS-SW-14 | D31: PIT-105 | E31: IV-108 | F31: Final Condenser - Outlet | G31: Pressure Indicating Transmitter | H31: Sea water | J31: =IFERROR(INDEX(Pressures_mbar,MATCH(INDEX(LOL_LineTags,MATCH(C31,LOL_LineNumbers,0)),LineTags,0)),IFERROR(INDEX(LOE_Pressures,MATCH(C31,LOE_EquipNames,0)),INDEX(LOE_Pressures,MATCH(C31,LOE_EquipTags,0)))) -> 3500 | M31: =IFERROR(INDEX(Temperatures,MATCH(INDEX(LOL_LineTags,MATCH(C31,LOL_LineNumbers,0)),LineTags,0)),IFERROR(INDEX(LOE_Temperatures,MATCH(C31,LOE_EquipNames,0)),INDEX(LOE_Temperatures,MATCH(C31,LOE_EquipTags,0)))) -> 33.90938 | P31: =IFERROR(INDEX(FlowRates_kghr,MATCH(INDEX(LOL_LineTags,MATCH(C31,LOL_LineNumbers,0)),LineTags,0)),"") -> 39600 | S31: =IFERROR(INDEX(TDS_Values,MATCH(INDEX(LOL_LineTags,MATCH(C31,LOL_LineNumbers,0)),LineTags,0)),"") -> 39504.432
A32: =A31+1 -> 29 | B32: SP40-01-03-001 | C32: ='LIST OF LINES'!B17 -> 100-40-SS-SW-14 | D32: TE-104 | F32: Final Condenser - Outlet | G32: Temperature Element with TW | H32: Sea water | J32: =IFERROR(INDEX(Pressures_mbar,MATCH(INDEX(LOL_LineTags,MATCH(C32,LOL_LineNumbers,0)),LineTags,0)),IFERROR(INDEX(LOE_Pressures,MATCH(C32,LOE_EquipNames,0)),INDEX(LOE_Pressures,MATCH(C32,LOE_EquipTags,0)))) -> 3500 | M32: =IFERROR(INDEX(Temperatures,MATCH(INDEX(LOL_LineTags,MATCH(C32,LOL_LineNumbers,0)),LineTags,0)),IFERROR(INDEX(LOE_Temperatures,MATCH(C32,LOE_EquipNames,0)),INDEX(LOE_Temperatures,MATCH(C32,LOE_EquipTags,0)))) -> 33.90938 | P32: =IFERROR(INDEX(FlowRates_kghr,MATCH(INDEX(LOL_LineTags,MATCH(C32,LOL_LineNumbers,0)),LineTags,0)),"") -> 39600 | S32: =IFERROR(INDEX(TDS_Values,MATCH(INDEX(LOL_LineTags,MATCH(C32,LOL_LineNumbers,0)),LineTags,0)),"") -> 39504.432
A33: =A32+1 -> 30 | B33: SP40-01-03-001 | C33: ='LIST OF LINES'!B17 -> 100-40-SS-SW-14 | D33: TIT-104 | F33: Final Condenser - Outlet | G33: Temperature Indicating Transmitter | H33: Sea water | J33: =IFERROR(INDEX(Pressures_mbar,MATCH(INDEX(LOL_LineTags,MATCH(C33,LOL_LineNumbers,0)),LineTags,0)),IFERROR(INDEX(LOE_Pressures,MATCH(C33,LOE_EquipNames,0)),INDEX(LOE_Pressures,MATCH(C33,LOE_EquipTags,0)))) -> 3500 | M33: =IFERROR(INDEX(Temperatures,MATCH(INDEX(LOL_LineTags,MATCH(C33,LOL_LineNumbers,0)),LineTags,0)),IFERROR(INDEX(LOE_Temperatures,MATCH(C33,LOE_EquipNames,0)),INDEX(LOE_Temperatures,MATCH(C33,LOE_EquipTags,0)))) -> 33.90938 | P33: =IFERROR(INDEX(FlowRates_kghr,MATCH(INDEX(LOL_LineTags,MATCH(C33,LOL_LineNumbers,0)),LineTags,0)),"") -> 39600 | S33: =IFERROR(INDEX(TDS_Values,MATCH(INDEX(LOL_LineTags,MATCH(C33,LOL_LineNumbers,0)),LineTags,0)),"") -> 39504.432
